<mujoco model="aliengo">
    <compiler angle="radian" meshdir="../meshes/"/>
    <size njmax="500" nconmax="100"/>
    <option integrator="Euler"/>
    <asset>
        <mesh name="trunk" file="trunk.stl"/>
        <mesh name="hip" file="hip.stl"/>
        <mesh name="thigh_mirror" file="thigh_mirror.stl"/>
        <mesh name="calf" file="calf.stl"/>
        <mesh name="thigh" file="thigh.stl"/>
    </asset>
    <worldbody>
        <body name="torso">
            <camera name="egocentric" pos=".25 0 .11" xyaxes="0 -1 0 0 0 1" fovy="90"/>
            <camera name="side_cam" pos="0 -1 0.1" mode="track" xyaxes="1 0 0 0 0 1" fovy="90"/>
            <camera name="back_cam" pos="-1.5 0 0" mode="track" xyaxes="0 -1 0 0 0 1" fovy="90"/>
            <inertial pos="0.008465 0.004045 -0.000763" quat="-2.12791e-05 0.708321 0.00248043 0.705886" mass="9.041"
                      diaginertia="0.174606 0.161174 0.033257"/>
            <geom type="mesh" contype="0" conaffinity="0" group="1" rgba="0 0 0 0.6" mesh="trunk"/>
            <geom size="0.3235 0.075 0.056" type="box" rgba="0 0 0 0"/>
            <site name="torso_sensor_site" group="4" size="0.001 0.001 0.001"/>
            <body name="FR_hip" pos="0.2399 -0.051 0">
                <inertial pos="-0.022191 -0.015144 -1.5e-05" quat="0.0135493 0.706835 -0.0117635 0.707151" mass="1.993"
                          diaginertia="0.00558695 0.00491009 0.00290132"/>
                <joint name="FR_hip_joint" pos="0 0 0" axis="1 0 0" limited="true" range="-1.22173 1.22173"/>
                <geom quat="0 1 0 0" type="mesh" contype="0" conaffinity="0" group="1" rgba="1 0.423529 0.0392157 0.6"
                      mesh="hip"/>
                <geom size="0.046 0.0209" pos="0 -0.083 0" quat="0.707107 0.707107 0 0" type="cylinder"
                      rgba="0 0 0 0"/>
                <body name="FR_thigh" pos="0 -0.083 0">
                    <inertial pos="-0.005607 0.003877 -0.048199" quat="0.694544 -0.0335669 -0.031246 0.717987"
                              mass="0.639" diaginertia="0.0058474 0.00571186 0.000324584"/>
                    <joint name="FR_thigh_joint" pos="0 0 0" axis="0 1 0"/>
                    <geom type="mesh" contype="0" conaffinity="0" group="1" rgba="1 0.423529 0.0392157 0.6"
                          mesh="thigh_mirror"/>
                    <geom size="0.125 0.0187 0.0215" pos="0 0 -0.125" quat="0.707107 0 0.707107 0" type="box"
                          rgba="0 0 0 0"/>
                    <body name="FR_calf" pos="0 0 -0.25">
                        <inertial pos="0.00215606 4.88427e-05 -0.166671" quat="0.707462 0.00517582 0.00535172 0.706712"
                                  mass="0.267" diaginertia="0.00690975 0.00689712 5.4885e-05"/>
                        <joint name="FR_calf_joint" pos="0 0 0" axis="0 1 0" limited="true" range="-2.77507 -0.645772"/>
                        <geom type="mesh" contype="0" conaffinity="0" group="1" rgba="1 0.423529 0.0392157 0.6"
                              mesh="calf"/>
                        <geom size="0.125 0.0104 0.008" pos="0 0 -0.125" quat="0.707107 0 0.707107 0" type="box"
                              rgba="0 0 0 0"/>
                        <body name="FR_foot" pos="0 0 -0.25">
                            <geom size="0.0165" pos="0 0 0" contype="0" conaffinity="0" group="1"
                                  rgba="0 0 0 0"/>
                            <geom size="0.0265" pos="0 0 0" rgba="0 0 0 0"/>
                        </body>
                    </body>
                </body>
            </body>
            <body name="FL_hip" pos="0.2399 0.051 0">
                <inertial pos="-0.022191 0.015144 -1.5e-05" quat="-0.0135493 0.706835 0.0117635 0.707151" mass="1.993"
                          diaginertia="0.00558695 0.00491009 0.00290132"/>
                <joint name="FL_hip_joint" pos="0 0 0" axis="1 0 0" limited="true" range="-1.22173 1.22173"/>
                <geom type="mesh" contype="0" conaffinity="0" group="1" rgba="1 0.423529 0.0392157 0.6" mesh="hip"/>
                <geom size="0.046 0.0209" pos="0 0.083 0" quat="0.707107 0.707107 0 0" type="cylinder"
                      rgba="0 0 0 0"/>
                <body name="FL_thigh" pos="0 0.083 0">
                    <inertial pos="-0.005607 -0.003877 -0.048199" quat="0.717987 -0.031246 -0.0335669 0.694544"
                              mass="0.639"
                              diaginertia="0.0058474 0.00571186 0.000324584"/>
                    <joint name="FL_thigh_joint" pos="0 0 0" axis="0 1 0"/>
                    <geom type="mesh" contype="0" conaffinity="0" group="1" rgba="1 0.423529 0.0392157 0.6"
                          mesh="thigh"/>
                    <geom size="0.125 0.0187 0.0215" pos="0 0 -0.125" quat="0.707107 0 0.707107 0" type="box"
                          rgba="0 0 0 0"/>
                    <body name="FL_calf" pos="0 0 -0.25">
                        <inertial pos="0.00215606 4.88427e-05 -0.166671" quat="0.707462 0.00517582 0.00535172 0.706712"
                                  mass="0.267" diaginertia="0.00690975 0.00689712 5.4885e-05"/>
                        <joint name="FL_calf_joint" pos="0 0 0" axis="0 1 0" limited="true" range="-2.77507 -0.645772"/>
                        <geom type="mesh" contype="0" conaffinity="0" group="1" rgba="1 0.423529 0.0392157 0.6"
                              mesh="calf"/>
                        <geom size="0.125 0.0104 0.008" pos="0 0 -0.125" quat="0.707107 0 0.707107 0" type="box"
                              rgba="0 0 0 0"/>
                        <body name="FL_foot" pos="0 0 -0.25">
                            <geom size="0.0165" pos="0 0 0" contype="0" conaffinity="0" group="1"
                                  rgba="0 0 0 0"/>
                            <geom size="0.0265" pos="0 0 0" rgba="0 0 0 0"/>
                        </body>
                    </body>
                </body>
            </body>
            <body name="RR_hip" pos="-0.2399 -0.051 0">
                <inertial pos="0.022191 -0.015144 -1.5e-05" quat="-0.0117635 0.707151 0.0135493 0.706835" mass="1.993"
                          diaginertia="0.00558695 0.00491009 0.00290132"/>
                <joint name="RR_hip_joint" pos="0 0 0" axis="1 0 0" limited="true" range="-1.22173 1.22173"/>
                <geom quat="0 0 0 -1" type="mesh" contype="0" conaffinity="0" group="1" rgba="1 0.423529 0.0392157 0.6"
                      mesh="hip"/>
                <geom size="0.046 0.0209" pos="0 -0.083 0" quat="0.707107 0.707107 0 0" type="cylinder"
                      rgba="0 0 0 0"/>
                <body name="RR_thigh" pos="0 -0.083 0">
                    <inertial pos="-0.005607 0.003877 -0.048199" quat="0.694544 -0.0335669 -0.031246 0.717987"
                              mass="0.639"
                              diaginertia="0.0058474 0.00571186 0.000324584"/>
                    <joint name="RR_thigh_joint" pos="0 0 0" axis="0 1 0"/>
                    <geom type="mesh" contype="0" conaffinity="0" group="1" rgba="1 0.423529 0.0392157 0.6"
                          mesh="thigh_mirror"/>
                    <geom size="0.125 0.0187 0.0215" pos="0 0 -0.125" quat="0.707107 0 0.707107 0" type="box"
                          rgba="0 0 0 0"/>
                    <body name="RR_calf" pos="0 0 -0.25">
                        <inertial pos="0.00215606 4.88427e-05 -0.166671" quat="0.707462 0.00517582 0.00535172 0.706712"
                                  mass="0.267" diaginertia="0.00690975 0.00689712 5.4885e-05"/>
                        <joint name="RR_calf_joint" pos="0 0 0" axis="0 1 0" limited="true" range="-2.77507 -0.645772"/>
                        <geom type="mesh" contype="0" conaffinity="0" group="1" rgba="1 0.423529 0.0392157 0.6"
                              mesh="calf"/>
                        <geom size="0.125 0.0104 0.008" pos="0 0 -0.125" quat="0.707107 0 0.707107 0" type="box"
                              rgba="0 0 0 0"/>
                        <body name="RR_foot" pos="0 0 -0.25">
                            <geom size="0.0165" pos="0 0 0" contype="0" conaffinity="0" group="1"
                                  rgba="0 0 0 0"/>
                            <geom size="0.0265" pos="0 0 0" rgba="0 0 0 0"/>
                        </body>
                    </body>
                </body>
            </body>
            <body name="RL_hip" pos="-0.2399 0.051 0">
                <inertial pos="0.022191 0.015144 -1.5e-05" quat="0.0117635 0.707151 -0.0135493 0.706835" mass="1.993"
                          diaginertia="0.00558695 0.00491009 0.00290132"/>
                <joint name="RL_hip_joint" pos="0 0 0" axis="1 0 0" limited="true" range="-1.22173 1.22173"/>
                <geom quat="0 0 1 0" type="mesh" contype="0" conaffinity="0" group="1" rgba="1 0.423529 0.0392157 0.6"
                      mesh="hip"/>
                <geom size="0.046 0.0209" pos="0 0.083 0" quat="0.707107 0.707107 0 0" type="cylinder"
                      rgba="0 0 0 0"/>
                <body name="RL_thigh" pos="0 0.083 0">
                    <inertial pos="-0.005607 -0.003877 -0.048199" quat="0.717987 -0.031246 -0.0335669 0.694544"
                              mass="0.639" diaginertia="0.0058474 0.00571186 0.000324584"/>
                    <joint name="RL_thigh_joint" pos="0 0 0" axis="0 1 0"/>
                    <geom type="mesh" contype="0" conaffinity="0" group="1" rgba="1 0.423529 0.0392157 0.6"
                          mesh="thigh"/>
                    <geom size="0.125 0.0187 0.0215" pos="0 0 -0.125" quat="0.707107 0 0.707107 0" type="box"
                          rgba="0 0 0 0"/>
                    <body name="RL_calf" pos="0 0 -0.25">
                        <inertial pos="0.00215606 4.88427e-05 -0.166671" quat="0.707462 0.00517582 0.00535172 0.706712"
                                  mass="0.267" diaginertia="0.00690975 0.00689712 5.4885e-05"/>
                        <joint name="RL_calf_joint" pos="0 0 0" axis="0 1 0" limited="true" range="-2.77507 -0.645772"/>
                        <geom type="mesh" contype="0" conaffinity="0" group="1" rgba="1 0.423529 0.0392157 0.6"
                              mesh="calf"/>
                        <geom size="0.125 0.0104 0.008" pos="0 0 -0.125" quat="0.707107 0 0.707107 0" type="box"
                              rgba="0 0 0 0"/>
                        <body name="RL_foot" pos="0 0 -0.25">
                            <geom size="0.0165" pos="0 0 0" contype="0" conaffinity="0" group="1"
                                  rgba="0 0 0 0"/>
                            <geom size="0.0265" pos="0 0 0" rgba="0 0 0 0"/>
                        </body>
                    </body>
                </body>
            </body>
        </body>
    </worldbody>
    <actuator>
        <motor name="FR_hip_joint" joint="FR_hip_joint"/>
        <motor name="FR_thigh_joint" joint="FR_thigh_joint"/>
        <motor name="FR_calf_joint" joint="FR_calf_joint"/>
        <motor name="FL_hip_joint" joint="FL_hip_joint"/>
        <motor name="FL_thigh_joint" joint="FL_thigh_joint"/>
        <motor name="FL_calf_joint" joint="FL_calf_joint"/>
        <motor name="RR_hip_joint" joint="RR_hip_joint"/>
        <motor name="RR_thigh_joint" joint="RR_thigh_joint"/>
        <motor name="RR_calf_joint" joint="RR_calf_joint"/>
        <motor name="RL_hip_joint" joint="RL_hip_joint"/>
        <motor name="RL_thigh_joint" joint="RL_thigh_joint"/>
        <motor name="RL_calf_joint" joint="RL_calf_joint"/>
    </actuator>
    <sensor>
        <accelerometer name="torso_accm" site="torso_sensor_site"/>
        <gyro name="torso_gyro" site="torso_sensor_site"/>
        <velocimeter name="torso_velm" site="torso_sensor_site"/>
    </sensor>
</mujoco>
